Workbook

Sheet Instructions
B1: Verifying Franchise Sales from BI:
B2: See spreadsheet with instructions here:
B3: Z:\Shared\Accounting\Franchise Accounting\Weekly Billing\Franchise Sales\2021
B6: Putting together Franchise Royalty Calculator:
B7: Rates from Tracker | C7: Add any new franchise locations & rate info to the bottom of the sheet.
D8: !! - Make sure if you add/remove franchisee's you check that the WF Template has the correct account informatio/amount pulling correctly
B9: Calculations | C9: Update cell O5 with the first date of the franchise week you are working on
C10: In B-F, copypasta data from the Franchise Sales from Tableau
D11: !! - Make sure you verified the data first! (see "Verifying Franchise Sales from Tableau" above)
D12: !! - Make sure you remove any remaining data from the previous week's listing (Scroll to bottom and check on dates vs billing week)
D13: !! - Confirm Check figure in Column F agrees to Franchise Sales file for net sales
C14: Update check figures formulas to current franchise sales week file
C15: The calculations in G-M should auto-populate. If they do not, make sure the "Rates from Tracker" tab is updated with the stores that are erroring out.
C16: Column P will also show a store count for each day - make sure this ties to your open store count from the "Rates from Tracker"
D17: Note: Northwestern University and DTW Airport is billed via a separate method (store does not use Brink as their POS)
B19: Summary | C19: Update cell B3 with the end date of the franchise week you are working on
C20: Refresh Pivot
C21: Update V.I.'s tax amount
B23: Debit Memo Info | C23: If there any new locations, add a row to the bottom of the sheet
C24: See below "To Create AR Invoice in SAP" instructions
B28: To Create AR Invoice in SAP:
B29: Debit Memo Info - tab
B31: Manage Debit Memo Requests - SAP
C32: Create Debit Memo Request
C33: DR / 1750 / 10 / 00
H43: 1753 CAD
B60: Filter on Franchisee (in Debit Memo Info Tab in order of summary franchisee)
B61: Sold to Party = Franchisee
B62: Cust. Reference = Date range of billing (ex. 1/14/19-1/20/19)
B63: Billing Date = last day of billing (ex. 1/20/19)
B64: Billing Block = blank
B92: Go to "Sales" tab
B93: **Billing Block should be BLANK
B94: Order Reason = Sales Call
B96: Create line items for "Continuingfee" and "Marketingfee", one for each line for the franchisee
B97: Quantity = 1
B98: Copy over Item Descriptions into corresponding line items
B130: Use this below to copy, paste in 'Material'and 'Target Quantiy' while creating invoice
B132: CONTINUINGFEE | C132: MARKETINGFEE | D132: 1 | F132: ppr0
B133: CONTINUINGFEE | C133: MARKETINGFEE | D133: 1
...

Sheet Rates from Tracker
A3: Franchise Locations & Royalty Info | I3: Royalty Fee End Dates
A4: Location | B4: Debit Memo Location | C4: Franchisee | D4: Principal Name | E4: Founders/Non-Founders | F4: Open Date | G4: Marketing/Royalty Fee Start | H4: Marketing & Royalty Fee End | I4: 2.5% | J4: Start Period | K4: End Period - 2% | L4: 2% | M4: End Period - 3% | N4: 3% | O4: End Period - 4% | P4: 4% | Q4: End Period - 5% | R4: 5% | S4: End Period - 6% | T4: 6% | U4: Column1
A5: Asheville | B5: Asheville | C5: RTHT Investments LLC | D5: Goldman | E5: Founders | F5: 42646 | G5: 42647 | H5: 46320 | J5: PERIOD 11 2016 | K5: PERIOD 11 2017 | L5: 43037 | M5: PERIOD 11 2018 | N5: 43408 | O5: PERIOD 11 2019 | P5: 43772 | Q5: PERIOD 11 2026 | R5: 46320 | S5: PERIOD 11 2026
A6: Auburn Village | B6: Auburn Village | C6: Exceed Group Auburn Village | D6: Chawla | E6: Non-Founders | F6: 42891 | G6: 42892 | H6: 46544 | J6: PERIOD 6 2017 | K6: PERIOD 6 2018 | L6: 43268 | M6: PERIOD 6 2019 | N6: 43632 | O6: PERIOD 6 2020 | P6: 43996 | Q6: PERIOD 6 2027 | R6: 46544 | S6: PERIOD 6 2027
A7: Berewick | B7: Berewick | C7: RTHT Investments LLC | D7: Goldman | E7: Non-Founders | F7: 42968 | G7: 42969 | H7: 46628 | I7: 43008 | J7: PERIOD 9 2017 | Q7: PERIOD 9 2027 | R7: 46628 | S7: PERIOD 9 2027
A8: Blue Springs | B8: Blue Springs | C8: Paceline Partners, LLC (KS/MO) | D8: Womack | E8: Non-Founders | F8: 42847 | G8: 42848 | H8: 46516 | I8: 42930 | J8: PERIOD 5 2017 | Q8: PERIOD 5 2027 | R8: 46516 | S8: PERIOD 5 2027
A9: Brighton | B9: Brighton | C9: TSFR Pizza LLC | D9: Schostak | E9: Founders | F9: 42361 | G9: 42362 | H9: 46012 | J9: PERIOD 13 2015 | K9: PERIOD 13 2016 | L9: 42729 | M9: PERIOD 13 2017 | N9: 43100 | O9: PERIOD 13 2018 | P9: 43464 | Q9: PERIOD 13 2025 | R9: 46012 | S9: PERIOD 13 2025
A10: Canton | B10: Canton | C10: TSFR Pizza LLC | D10: Schostak | E10: Founders | F10: 42755 | G10: 42756 | H10: 46404 | J10: PERIOD 1 2017 | K10: PERIOD 1 2018 | L10: 43128 | M10: PERIOD 1 2019 | N10: 43492 | O10: PERIOD 1 2020 | P10: 43856 | Q10: PERIOD 1 2027 | R10: 46404 | S10: PERIOD 1 2027
A11: Carolina Forest | B11: Carolina Forest | C11: Rolling Dough LLC | D11: Connolly | E11: Founders | F11: 42879 | G11: 42880 | H11: 46544 | J11: PERIOD 6 2017 | K11: PERIOD 6 2018 | L11: 43268 | M11: PERIOD 6 2019 | N11: 43632 | O11: PERIOD 6 2020 | P11: 43996 | Q11: PERIOD 6 2027 | R11: 46544 | S11: PERIOD 6 2027
A12: Castle Rock | B12: Castle Rock | C12: Best Pizza LLC | D12: Merullo | E12: Founders | F12: 42373 | G12: 42374 | H12: 46040 | J12: PERIOD 1 2016 | K12: PERIOD 1 2017 | L12: 42757 | M12: PERIOD 1 2018 | N12: 43128 | O12: PERIOD 1 2019 | P12: 43492 | Q12: PERIOD 1 2026 | R12: 46040 | S12: PERIOD 1 2026
A13: Centre Avenue | B13: Centre Avenue | C13: Best Pizza LLC | D13: Merullo | E13: Founders | F13: 42667 | G13: 42668 | H13: 46320 | J13: PERIOD 11 2016 | K13: PERIOD 11 2017 | L13: 43037 | M13: PERIOD 11 2018 | N13: 43408 | O13: PERIOD 11 2019 | P13: 43772 | Q13: PERIOD 11 2026 | R13: 46320 | S13: PERIOD 11 2026
A14: Chesterfield Township | B14: Chesterfield Township | C14: TSFR Pizza LLC | D14: Schostak | E14: Founders | F14: 42749 | G14: 42750 | H14: 46404 | J14: PERIOD 1 2017 | K14: PERIOD 1 2018 | L14: 43128 | M14: PERIOD 1 2019 | N14: 43492 | O14: PERIOD 1 2020 | P14: 43856 | Q14: PERIOD 1 2027 | R14: 46404 | S14: PERIOD 1 2027
A15: Chico | B15: Chico | C15: Exceed Group Chico | D15: Chawla | E15: Non-Founders | F15: 42646 | G15: 42647 | H15: 46320 | J15: PERIOD 11 2016 | K15: PERIOD 11 2017 | L15: 43037 | M15: PERIOD 11 2018 | N15: 43408 | O15: PERIOD 11 2019 | P15: 43772 | Q15: PERIOD 11 2026 | R15: 46320 | S15: PERIOD 11 2026
A16: Dublin Commons | B16: Dublin Commons | C16: Best Pizza LLC | D16: Merullo | E16: Non-Founders | F16: 42983 | G16: 42984 | H16: 46656 | I16: 43008 | J16: PERIOD 10 2017 | Q16: PERIOD 10 2027 | R16: 46656 | S16: PERIOD 10 2027
A17: Englewood | B17: Englewood #5 | C17: Cool Dough Development, LLC | D17: Denning | E17: Non-Founders | F17: 42865 | G17: 42866 | H17: 46516 | I17: 42948 | J17: PERIOD 5 2017 | Q17: PERIOD 5 2027 | R17: 46516 | S17: PERIOD 5 2027
A18: Evansville | B18: Evansville #11 | C18: Cool Dough Development, LLC | D18: Denning | E18: Non-Founders | F18: 42949 | G18: 42950 | H18: 46600 | I18: 43032 | J18: PERIOD 8 2017 | Q18: PERIOD 8 2027 | R18: 46600 | S18: PERIOD 8 2027
A19: Falcon Landing | B19: Falcon Landing | C19: Best Pizza LLC | D19: Merullo | E19: Founders | F19: 42292 | G19: 42293 | H19: 45956 | J19: PERIOD 11 2015 | K19: PERIOD 11 2016 | L19: 42673 | M19: PERIOD 11 2017 | N19: 43037 | O19: PERIOD 11 2018 | P19: 43408 | Q19: PERIOD 11 2025 | R19: 45956 | S19: PERIOD 11 2025
A20: Fayetteville | B20: Fayetteville | C20: RTHT Investments LLC | D20: Goldman | E20: Founders | F20: 42324 | G20: 42325 | H20: 45984 | J20: PERIOD 12 2015 | K20: PERIOD 12 2016 | L20: 42701 | M20: PERIOD 12 2017 | N20: 43065 | O20: PERIOD 12 2018 | P20: 43436 | Q20: PERIOD 12 2025 | R20: 45984 | S20: PERIOD 12 2025
A21: Forest Trace | B21: Forest Trace | C21: Best Pizza LLC | D21: Merullo | E21: Founders | F21: 42662 | G21: 42663 | H21: 46320 | J21: PERIOD 11 2016 | K21: PERIOD 11 2017 | L21: 43037 | M21: PERIOD 11 2018 | N21: 43408 | O21: PERIOD 11 2019 | P21: 43772 | Q21: PERIOD 11 2026 | R21: 46320 | S21: PERIOD 11 2026
A22: Gahanna | B22: Gahanna | C22: Paceline Partners, LLC (OH) | D22: Womack | E22: Non-Founders | F22: 42662 | G22: 42663 | H22: 46320 | I22: 42745 | J22: PERIOD 11 2016 | Q22: PERIOD 11 2026 | R22: 46320 | S22: PERIOD 11 2026
A23: Hamburg | B23: Hamburg #6 | C23: Cool Dough Development, LLC | D23: Denning | E23: Non-Founders | F23: 42641 | G23: 42642 | H23: 46292 | I23: 42724 | J23: PERIOD 10 2016 | Q23: PERIOD 10 2026 | R23: 46292 | S23: PERIOD 10 2026
A24: Hikes Point | B24: Hikes Point #1 | C24: Cool Dough Development, LLC | D24: Denning | E24: Non-Founders | F24: 42571 | G24: 42572 | H24: 46236 | I24: 42654 | J24: PERIOD 8 2016 | Q24: PERIOD 8 2026 | R24: 46236 | S24: PERIOD 8 2026
A25: Howe Bout Arden | B25: Howe Bout Arden | C25: Exceed Group Howe Bout Arden | D25: Chawla | E25: Non-Founders | F25: 42404 | G25: 42405 | H25: 46068 | J25: PERIOD 2 2016 | K25: PERIOD 2 2017 | L25: 42785 | M25: PERIOD 2 2018 | N25: 43156 | O25: PERIOD 2 2019 | P25: 43520 | Q25: PERIOD 2 2026 | R25: 46068 | S25: PERIOD 2 2026
A26: Kennesaw | B26: Kennesaw | C26: Southern Pie LLC | D26: Hill/Hayden | E26: Non-Founders | F26: 42891 | G26: 42892 | H26: 46544 | I26: 42974 | J26: PERIOD 6 2017 | Q26: PERIOD 6 2027 | R26: 46544 | S26: PERIOD 6 2027
A27: King & Calhoun | B27: King & Calhoun | C27: Rolling Dough LLC | D27: Connolly | E27: Founders | F27: 42427 | G27: 42428 | H27: 46096 | J27: PERIOD 3 2016 | K27: PERIOD 3 2017 | L27: 42813 | M27: PERIOD 3 2018 | N27: 43184 | O27: PERIOD 3 2019 | P27: 43548 | Q27: PERIOD 3 2026 | R27: 46096 | S27: PERIOD 3 2026 | U27: Closed
A28: Liberty Triangle | B28: Liberty Triangle | C28: Paceline Partners, LLC (KS/MO) | D28: Womack | E28: Non-Founders | F28: 42634 | G28: 42635 | H28: 46292 | I28: 42717 | J28: PERIOD 10 2016 | Q28: PERIOD 10 2026 | R28: 46292 | S28: PERIOD 10 2026
A29: LIVONIA | B29: LIVONIA | C29: TSFR Pizza LLC | D29: Schostak | E29: Founders | F29: 42178 | G29: 42179 | H29: 45844 | J29: PERIOD 7 2015 | K29: PERIOD 7 2016 | L29: 42561 | M29: PERIOD 7 2017 | N29: 42925 | O29: PERIOD 7 2018 | P29: 43296 | Q29: PERIOD 7 2025 | R29: 45844 | S29: PERIOD 7 2025
A30: Matthews | B30: Matthews | C30: RTHT Investments LLC | D30: Goldman | E30: Non-Founders | F30: 42913 | G30: 42914 | H30: 46572 | J30: PERIOD 7 2017 | K30: PERIOD 7 2018 | M30: PERIOD 7 2019 | O30: PERIOD 7 2020 | Q30: PERIOD 7 2027 | R30: 46572 | S30: PERIOD 7 2027
A31: McCaslin Marketplace | B31: McCaslin Marketplace | C31: Best Pizza LLC | D31: Merullo | E31: Founders | F31: 42641 | G31: 42642 | H31: 46292 | J31: PERIOD 10 2016 | K31: PERIOD 10 2017 | L31: 43009 | M31: PERIOD 10 2018 | N31: 43380 | O31: PERIOD 10 2019 | P31: 43744 | Q31: PERIOD 10 2026 | R31: 46292 | S31: PERIOD 10 2026
A32: Millbrook Road | B32: Millbrook Road | C32: RTHT Investments LLC | D32: Goldman | E32: Founders | F32: 42234 | G32: 42235 | H32: 45900 | J32: PERIOD 9 2015 | K32: PERIOD 9 2016 | L32: 42617 | M32: PERIOD 9 2017 | N32: 42981 | O32: PERIOD 9 2018 | P32: 43352 | Q32: PERIOD 9 2025 | R32: 45900 | S32: PERIOD 9 2025
A33: Morse Road | B33: Morse Road | C33: Paceline Partners, LLC (OH) | D33: Womack | E33: Non-Founders | F33: 42826 | G33: 42827 | H33: 46488 | I33: 42909 | J33: PERIOD 4 2017 | Q33: PERIOD 4 2027 | R33: 46488 | S33: PERIOD 4 2027
A34: NE Columbia | B34: NE Columbia | C34: Rolling Dough LLC | D34: Connolly | E34: Founders | F34: 42820 | G34: 42821 | H34: 46488 | J34: PERIOD 4 2017 | K34: PERIOD 4 2018 | L34: 43212 | M34: PERIOD 4 2019 | N34: 43576 | O34: PERIOD 4 2020 | P34: 43940 | Q34: PERIOD 4 2027 | R34: 46488 | S34: PERIOD 4 2027
A35: North Charleston | B35: North Charleston | C35: Rolling Dough LLC | D35: Connolly | E35: Founders | F35: 42642 | G35: 42643 | H35: 46292 | J35: PERIOD 10 2016 | K35: PERIOD 10 2017 | L35: 43009 | M35: PERIOD 10 2018 | N35: 43380 | O35: PERIOD 10 2019 | P35: 43744 | Q35: PERIOD 10 2026 | R35: 46292 | S35: PERIOD 10 2026
A36: North Myrtle Beach | B36: North Myrtle Beach | C36: Rolling Dough LLC | D36: Connolly | E36: Founders | F36: 42468 | G36: 42469 | H36: 46124 | J36: PERIOD 4 2016 | K36: PERIOD 4 2017 | L36: 42841 | M36: PERIOD 4 2018 | N36: 43212 | O36: PERIOD 4 2019 | P36: 43576 | Q36: PERIOD 4 2026 | R36: 46124 | S36: PERIOD 4 2026
A37: Northville | B37: Northville | C37: TSFR Pizza LLC | D37: Schostak | E37: Founders | F37: 42231 | G37: 42232 | H37: 45900 | J37: PERIOD 9 2015 | K37: PERIOD 9 2016 | L37: 42617 | M37: PERIOD 9 2017 | N37: 42981 | O37: PERIOD 9 2018 | P37: 43352 | Q37: PERIOD 9 2025 | R37: 45900 | S37: PERIOD 9 2025
A38: Oakley | B38: Oakley #2 | C38: Cool Dough Development, LLC | D38: Denning | E38: Non-Founders | F38: 42662 | G38: 42663 | H38: 46320 | I38: 42745 | J38: PERIOD 11 2016 | Q38: PERIOD 11 2026 | R38: 46320 | S38: PERIOD 11 2026
A39: Owensboro | B39: Owensboro #8 | C39: Cool Dough Development, LLC | D39: Denning | E39: Non-Founders | F39: 42781 | G39: 42782 | H39: 46432 | I39: 42864 | J39: PERIOD 2 2017 | Q39: PERIOD 2 2027 | R39: 46432 | S39: PERIOD 2 2027
A40: Park Meadows | B40: Park Meadows | C40: Best Pizza LLC | D40: Merullo | E40: Founders | F40: 41892 | G40: 41893 | H40: 45564 | J40: PERIOD 10 2014 | K40: PERIOD 10 2015 | L40: 42281 | M40: PERIOD 10 2016 | N40: 42645 | O40: PERIOD 10 2017 | P40: 43009 | Q40: PERIOD 10 2024 | R40: 45564 | S40: PERIOD 10 2024
A41: Polaris | B41: Polaris | C41: Paceline Partners, LLC (OH) | D41: Womack | E41: Non-Founders | F41: 42748 | G41: 42749 | H41: 46404 | I41: 42831 | J41: PERIOD 1 2017 | Q41: PERIOD 1 2027 | R41: 46404 | S41: PERIOD 1 2027
A42: Raymore | B42: Raymore | C42: Paceline Partners, LLC (KS/MO) | D42: Womack | E42: Non-Founders | F42: 42942 | G42: 42943 | H42: 46600 | I42: 43025 | J42: PERIOD 8 2017 | Q42: PERIOD 8 2027 | R42: 46600 | S42: PERIOD 8 2027
...

Sheet Food Truck Sales - To Date
A1: Date | B1: Sum of MOD # | C1: Store | D1: Gross Sales | E1: Net Sales
A2: 43252 | C2: Food Truck - Florida | D2: 331.85 | E2: 144.85
A3: 43262 | C3: Food Truck - Florida | D3: 500.56 | E3: 500.56
A4: 43263 | C4: Food Truck - Florida | D4: 650.28 | E4: 650.28
A5: 43266 | C5: Food Truck - Florida | D5: 882.2 | E5: 0
A6: 43267 | C6: Food Truck - Florida | D6: 1612.02 | E6: 1498.02
A7: 43280 | C7: Food Truck - Florida | D7: 1604 | E7: 1604
A8: 43288 | C8: Food Truck - Florida | D8: 39.64 | E8: 39.64
A9: 43302 | C9: Food Truck - Florida | D9: 607.22 | E9: 607.22
A10: 43321 | C10: Food Truck - Florida | D10: 1684.2 | E10: 1684.2
A11: 43350 | C11: Food Truck - Florida | D11: 686.55 | E11: 686.55
A12: 43351 | C12: Food Truck - Florida | D12: 718.17 | E12: 702.13
A13: 43357 | C13: Food Truck - Florida | D13: 1652.12 | E13: 1652.12
... A16: 43379 | C16: Food Truck - Florida | D16: 897.93 | E16: 897.93
A17: 43387 | B17: 504 | C17: Food Truck - Florida | D17: 495.86 | E17: 495.86
A18: 43389 | B18: 504 | C18: Food Truck - Florida | D18: 433.08 | E18: 368.12
A19: 43398 | B19: 504 | C19: Food Truck - Florida | D19: 589.29 | E19: 571.36
A20: 43399 | B20: 504 | C20: Food Truck - Florida | D20: 2147.85 | E20: 2131.81
A21: 43400 | B21: 504 | C21: Food Truck - Florida | D21: 17.77 | E21: 17.77
A22: 43407 | B22: 504 | C22: Food Truck - Florida | D22: 1956.1 | E22: 1956.1
A23: 43408 | B23: 504 | C23: Food Truck - Florida | D23: 1286.07 | E23: 1165.77
A24: 43420 | B24: 504 | C24: Food Truck - Florida | D24: 1150.74 | E24: 1150.74
A25: 43424 | B25: 504 | C25: Food Truck - Florida | D25: 667.55 | E25: 667.55
A26: 43429 | B26: 504 | C26: Food Truck - Florida | D26: 561.4 | E26: 449.12
A27: 43430 | B27: 504 | C27: Food Truck - Florida | D27: 312.78 | E27: 312.78
A28: 43432 | B28: 504 | C28: Food Truck - Florida | D28: 127.86 | E28: 79.74
... A60: 43526 | B60: 504 | C60: Food Truck - Florida | D60: 1007.93 | E60: 873.29
A61: Total | D61: =SUBTOTAL(109,Table1[Gross Sales]) -> 46717.74 | E61: =SUBTOTAL(109,Table1[Net Sales]) -> 40271.14

Sheet Calculations
C1: =IF(SUM(A5:A424)>0,"CHECK BILLING DATES","GOOD") -> GOOD | D1: Check Figures | E1: =SUM(E5:E1048576)-SUM('[1]Tableau Data'!$D:$D) -> #REF! | F1: =SUM(F5:F1048576)-SUM('[1]Tableau Data'!$E:$E) -> #REF! | L1: Check figure for # of lines | M1: =COUNTA(M5:M590)-COUNTA(D5:D590) -> 0
D2: Discrepancy should be tates creek fees as we abated them as of 10/31/22
B3: Tableau/Brink Data | G3: Calculations
B4: Date | C4: Sum of MOD # | D4: Store | E4: Column1 | F4: Column2 | G4: Location | H4: Franchisee | I4: Principal Name | J4: Marketing Fee | K4: Royalty Rate | L4: Royalty Fee | M4: Total | O4: Date | P4: # Stores | Q4: Comments
A5: =IF(Table11[[#This Row],[Date]]=0,"",IF(Table11[[#This Row],[Date]]<(Summary!$B$3-6),1,"")) | B5: 46271 | C5: 21 | D5: Park Meadows | E5: 3283.05 | F5: 3113.23 | G5: =VLOOKUP(Table11[[#This Row],[Store]],'Rates from Tracker'!A:B,2,0) -> Park Meadows | H5: =VLOOKUP(D5,'Rates from Tracker'!A:C,3,0) -> Best Pizza LLC | I5: =VLOOKUP(Table11[[#This Row],[Franchisee]],'Rates from Tracker'!C:D,2,0) -> Merullo | J5: =ROUND(IF(Table11[[#This Row],[Location]]="Belmont Market",Table11[[#This Row],[Column2]]*0.01,IF(Table11[[#This Row],[Location]]="Country Club Centre",Table11[[#This Row],[Column2]]*0.01,IF(Table11[[#This Row],[Location]]="Naval Air Station Norfolk",Table11[[#This Row],[Column2]]*0.005,F5*0.02))),2) -> 62.26 | K5: =IF(Table11[[#This Row],[Location]]="Creekwalk",0.02,IF(Table11[[#This Row],[Location]]="Country Club Centre",0.01,IF(Table11[[#This Row],[Location]]="Lenexa",0.02,IF(Table11[[#This Row],[Location]]="Belmont Market",0.02,IF(Table11[[#This Row],[Location]]="Naval Air Station Norfolk",0.02,IF(Table11[[#This Row],[Location]]="Madison",0.01,IF(Table11[[#This Row],[Location]]="Mobile",0.01,IF(Table11[[#This Row],[Location]]="Decatur",0.01,IF(Table11[[#This Row],[Location]]="Woods Cross",0.01,IF(Table11[[#This Row],[Location]]="Park City",0.01,IF(Table11[[#This Row],[Location]]="Riverdale",0.01,IF(Table11[[#This Row],[Location]]="Riverton",0.01,IF(Table11[[#This Row],[Location]]="Layton",0.01,IF(Table11[[#This Row],[Location]]="Bend",0.01,IF(Table11[[#This Row],[Location]]="Bend",0.01,IF(Table11[[#This Row],[Location]]="Oakway",0.01,IF(Table11[[#This Row],[Location]]="North Medford",0.01,IF(Table11[[#This Row],[Location]]="South Eugene",0.01,IF(Table11[[#This Row],[Location]]="American Fork",0.01,IF(Table11[[#This Row],[Location]]="Sugar House",0.01,IF(Table11[[#This Row],[Location]]="Bend North",0.01,IF(Table11[[#This Row],[Location]]="South Medford",0.01,IF(Table11[[#This Row],[Location]]="Saratoga Springs",0.01,IF(Table11[[#This Row],[Location]]="Fort Union",0.01,IF(Table11[[#This Row],[Location]]="South Jordan",0.01,IF(Table11[[#This Row],[Location]]="Grants Pass",0.01,IF(Table11[[#This Row],[Location]]="Pocatello",0.01,IF(Table11[[#This Row],[Location]]="Spanish Fork",0.01,IF(Table11[[#This Row],[Location]]="Downtown Boise",0.01,IF(Table11[[#This Row],[Location]]="Boise Town Square",0.01,IF(Table11[[#This Row],[Location]]="Ammon",0.01,IF(Table11[[#This Row],[Location]]="Roseburg",0.01,IF(Table11[[#This Row],[Location]]="Springfield-Oregon",0.01,0.05))))))))))))))))))))))))))))))))) -> 0.05 | L5: =ROUND(F5*K5,2) -> 155.66 | M5: =J5+L5 -> 217.92 | O5: 46265 | P5: =COUNTIF(B:B,O5) -> 76
A6: =IF(Table11[[#This Row],[Date]]=0,"",IF(Table11[[#This Row],[Date]]<(Summary!$B$3-6),1,"")) | B6: 46271 | C6: 47 | D6: Redding | E6: 5116.92 | F6: 4816.47 | G6: =VLOOKUP(Table11[[#This Row],[Store]],'Rates from Tracker'!A:B,2,0) -> REDDING | H6: =VLOOKUP(D6,'Rates from Tracker'!A:C,3,0) -> Exceed Group REDDING | I6: =VLOOKUP(Table11[[#This Row],[Franchisee]],'Rates from Tracker'!C:D,2,0) -> Chawla | J6: =ROUND(IF(Table11[[#This Row],[Location]]="Belmont Market",Table11[[#This Row],[Column2]]*0.01,IF(Table11[[#This Row],[Location]]="Country Club Centre",Table11[[#This Row],[Column2]]*0.01,IF(Table11[[#This Row],[Location]]="Naval Air Station Norfolk",Table11[[#This Row],[Column2]]*0.005,F6*0.02))),2) -> 96.33 | K6: =IF(Table11[[#This Row],[Location]]="Creekwalk",0.02,IF(Table11[[#This Row],[Location]]="Country Club Centre",0.01,IF(Table11[[#This Row],[Location]]="Lenexa",0.02,IF(Table11[[#This Row],[Location]]="Belmont Market",0.02,IF(Table11[[#This Row],[Location]]="Naval Air Station Norfolk",0.02,IF(Table11[[#This Row],[Location]]="Madison",0.01,IF(Table11[[#This Row],[Location]]="Mobile",0.01,IF(Table11[[#This Row],[Location]]="Decatur",0.01,IF(Table11[[#This Row],[Location]]="Woods Cross",0.01,IF(Table11[[#This Row],[Location]]="Park City",0.01,IF(Table11[[#This Row],[Location]]="Riverdale",0.01,IF(Table11[[#This Row],[Location]]="Riverton",0.01,IF(Table11[[#This Row],[Location]]="Layton",0.01,IF(Table11[[#This Row],[Location]]="Bend",0.01,IF(Table11[[#This Row],[Location]]="Bend",0.01,IF(Table11[[#This Row],[Location]]="Oakway",0.01,IF(Table11[[#This Row],[Location]]="North Medford",0.01,IF(Table11[[#This Row],[Location]]="South Eugene",0.01,IF(Table11[[#This Row],[Location]]="American Fork",0.01,IF(Table11[[#This Row],[Location]]="Sugar House",0.01,IF(Table11[[#This Row],[Location]]="Bend North",0.01,IF(Table11[[#This Row],[Location]]="South Medford",0.01,IF(Table11[[#This Row],[Location]]="Saratoga Springs",0.01,IF(Table11[[#This Row],[Location]]="Fort Union",0.01,IF(Table11[[#This Row],[Location]]="South Jordan",0.01,IF(Table11[[#This Row],[Location]]="Grants Pass",0.01,IF(Table11[[#This Row],[Location]]="Pocatello",0.01,IF(Table11[[#This Row],[Location]]="Spanish Fork",0.01,IF(Table11[[#This Row],[Location]]="Downtown Boise",0.01,IF(Table11[[#This Row],[Location]]="Boise Town Square",0.01,IF(Table11[[#This Row],[Location]]="Ammon",0.01,IF(Table11[[#This Row],[Location]]="Roseburg",0.01,IF(Table11[[#This Row],[Location]]="Springfield-Oregon",0.01,0.05))))))))))))))))))))))))))))))))) -> 0.05 | L6: =ROUND(F6*K6,2) -> 240.82 | M6: =J6+L6 -> 337.15 | O6: =O5+1 -> 46266 | P6: =COUNTIF(B:B,O6) -> 76
A7: =IF(Table11[[#This Row],[Date]]=0,"",IF(Table11[[#This Row],[Date]]<(Summary!$B$3-6),1,"")) | B7: 46271 | C7: 55 | D7: Rocklin | E7: 3552.05 | F7: 3144.19 | G7: =VLOOKUP(Table11[[#This Row],[Store]],'Rates from Tracker'!A:B,2,0) -> ROCKLIN | H7: =VLOOKUP(D7,'Rates from Tracker'!A:C,3,0) -> Exceed Group ROCKLIN | I7: =VLOOKUP(Table11[[#This Row],[Franchisee]],'Rates from Tracker'!C:D,2,0) -> Chawla | J7: =ROUND(IF(Table11[[#This Row],[Location]]="Belmont Market",Table11[[#This Row],[Column2]]*0.01,IF(Table11[[#This Row],[Location]]="Country Club Centre",Table11[[#This Row],[Column2]]*0.01,IF(Table11[[#This Row],[Location]]="Naval Air Station Norfolk",Table11[[#This Row],[Column2]]*0.005,F7*0.02))),2) -> 62.88 | K7: =IF(Table11[[#This Row],[Location]]="Creekwalk",0.02,IF(Table11[[#This Row],[Location]]="Country Club Centre",0.01,IF(Table11[[#This Row],[Location]]="Lenexa",0.02,IF(Table11[[#This Row],[Location]]="Belmont Market",0.02,IF(Table11[[#This Row],[Location]]="Naval Air Station Norfolk",0.02,IF(Table11[[#This Row],[Location]]="Madison",0.01,IF(Table11[[#This Row],[Location]]="Mobile",0.01,IF(Table11[[#This Row],[Location]]="Decatur",0.01,IF(Table11[[#This Row],[Location]]="Woods Cross",0.01,IF(Table11[[#This Row],[Location]]="Park City",0.01,IF(Table11[[#This Row],[Location]]="Riverdale",0.01,IF(Table11[[#This Row],[Location]]="Riverton",0.01,IF(Table11[[#This Row],[Location]]="Layton",0.01,IF(Table11[[#This Row],[Location]]="Bend",0.01,IF(Table11[[#This Row],[Location]]="Bend",0.01,IF(Table11[[#This Row],[Location]]="Oakway",0.01,IF(Table11[[#This Row],[Location]]="North Medford",0.01,IF(Table11[[#This Row],[Location]]="South Eugene",0.01,IF(Table11[[#This Row],[Location]]="American Fork",0.01,IF(Table11[[#This Row],[Location]]="Sugar House",0.01,IF(Table11[[#This Row],[Location]]="Bend North",0.01,IF(Table11[[#This Row],[Location]]="South Medford",0.01,IF(Table11[[#This Row],[Location]]="Saratoga Springs",0.01,IF(Table11[[#This Row],[Location]]="Fort Union",0.01,IF(Table11[[#This Row],[Location]]="South Jordan",0.01,IF(Table11[[#This Row],[Location]]="Grants Pass",0.01,IF(Table11[[#This Row],[Location]]="Pocatello",0.01,IF(Table11[[#This Row],[Location]]="Spanish Fork",0.01,IF(Table11[[#This Row],[Location]]="Downtown Boise",0.01,IF(Table11[[#This Row],[Location]]="Boise Town Square",0.01,IF(Table11[[#This Row],[Location]]="Ammon",0.01,IF(Table11[[#This Row],[Location]]="Roseburg",0.01,IF(Table11[[#This Row],[Location]]="Springfield-Oregon",0.01,0.05))))))))))))))))))))))))))))))))) -> 0.05 | L7: =ROUND(F7*K7,2) -> 157.21 | M7: =J7+L7 -> 220.09 | O7: =O6+1 -> 46267 | P7: =COUNTIF(B:B,O7) -> 76
A8: =IF(Table11[[#This Row],[Date]]=0,"",IF(Table11[[#This Row],[Date]]<(Summary!$B$3-6),1,"")) | B8: 46271 | C8: 56 | D8: Livonia | E8: 2880.02 | F8: 2726.86 | G8: =VLOOKUP(Table11[[#This Row],[Store]],'Rates from Tracker'!A:B,2,0) -> LIVONIA | H8: =VLOOKUP(D8,'Rates from Tracker'!A:C,3,0) -> TSFR Pizza LLC | I8: =VLOOKUP(Table11[[#This Row],[Franchisee]],'Rates from Tracker'!C:D,2,0) -> Schostak | J8: =ROUND(IF(Table11[[#This Row],[Location]]="Belmont Market",Table11[[#This Row],[Column2]]*0.01,IF(Table11[[#This Row],[Location]]="Country Club Centre",Table11[[#This Row],[Column2]]*0.01,IF(Table11[[#This Row],[Location]]="Naval Air Station Norfolk",Table11[[#This Row],[Column2]]*0.005,F8*0.02))),2) -> 54.54 | K8: =IF(Table11[[#This Row],[Location]]="Creekwalk",0.02,IF(Table11[[#This Row],[Location]]="Country Club Centre",0.01,IF(Table11[[#This Row],[Location]]="Lenexa",0.02,IF(Table11[[#This Row],[Location]]="Belmont Market",0.02,IF(Table11[[#This Row],[Location]]="Naval Air Station Norfolk",0.02,IF(Table11[[#This Row],[Location]]="Madison",0.01,IF(Table11[[#This Row],[Location]]="Mobile",0.01,IF(Table11[[#This Row],[Location]]="Decatur",0.01,IF(Table11[[#This Row],[Location]]="Woods Cross",0.01,IF(Table11[[#This Row],[Location]]="Park City",0.01,IF(Table11[[#This Row],[Location]]="Riverdale",0.01,IF(Table11[[#This Row],[Location]]="Riverton",0.01,IF(Table11[[#This Row],[Location]]="Layton",0.01,IF(Table11[[#This Row],[Location]]="Bend",0.01,IF(Table11[[#This Row],[Location]]="Bend",0.01,IF(Table11[[#This Row],[Location]]="Oakway",0.01,IF(Table11[[#This Row],[Location]]="North Medford",0.01,IF(Table11[[#This Row],[Location]]="South Eugene",0.01,IF(Table11[[#This Row],[Location]]="American Fork",0.01,IF(Table11[[#This Row],[Location]]="Sugar House",0.01,IF(Table11[[#This Row],[Location]]="Bend North",0.01,IF(Table11[[#This Row],[Location]]="South Medford",0.01,IF(Table11[[#This Row],[Location]]="Saratoga Springs",0.01,IF(Table11[[#This Row],[Location]]="Fort Union",0.01,IF(Table11[[#This Row],[Location]]="South Jordan",0.01,IF(Table11[[#This Row],[Location]]="Grants Pass",0.01,IF(Table11[[#This Row],[Location]]="Pocatello",0.01,IF(Table11[[#This Row],[Location]]="Spanish Fork",0.01,IF(Table11[[#This Row],[Location]]="Downtown Boise",0.01,IF(Table11[[#This Row],[Location]]="Boise Town Square",0.01,IF(Table11[[#This Row],[Location]]="Ammon",0.01,IF(Table11[[#This Row],[Location]]="Roseburg",0.01,IF(Table11[[#This Row],[Location]]="Springfield-Oregon",0.01,0.05))))))))))))))))))))))))))))))))) -> 0.05 | L8: =ROUND(F8*K8,2) -> 136.34 | M8: =J8+L8 -> 190.88 | O8: =O7+1 -> 46268 | P8: =COUNTIF(B:B,O8) -> 76
A9: =IF(Table11[[#This Row],[Date]]=0,"",IF(Table11[[#This Row],[Date]]<(Summary!$B$3-6),1,"")) | B9: 46271 | C9: 77 | D9: Falcon Landing | E9: 3632.62 | F9: 3442.4 | G9: =VLOOKUP(Table11[[#This Row],[Store]],'Rates from Tracker'!A:B,2,0) -> Falcon Landing | H9: =VLOOKUP(D9,'Rates from Tracker'!A:C,3,0) -> Best Pizza LLC | I9: =VLOOKUP(Table11[[#This Row],[Franchisee]],'Rates from Tracker'!C:D,2,0) -> Merullo | J9: =ROUND(IF(Table11[[#This Row],[Location]]="Belmont Market",Table11[[#This Row],[Column2]]*0.01,IF(Table11[[#This Row],[Location]]="Country Club Centre",Table11[[#This Row],[Column2]]*0.01,IF(Table11[[#This Row],[Location]]="Naval Air Station Norfolk",Table11[[#This Row],[Column2]]*0.005,F9*0.02))),2) -> 68.85 | K9: =IF(Table11[[#This Row],[Location]]="Creekwalk",0.02,IF(Table11[[#This Row],[Location]]="Country Club Centre",0.01,IF(Table11[[#This Row],[Location]]="Lenexa",0.02,IF(Table11[[#This Row],[Location]]="Belmont Market",0.02,IF(Table11[[#This Row],[Location]]="Naval Air Station Norfolk",0.02,IF(Table11[[#This Row],[Location]]="Madison",0.01,IF(Table11[[#This Row],[Location]]="Mobile",0.01,IF(Table11[[#This Row],[Location]]="Decatur",0.01,IF(Table11[[#This Row],[Location]]="Woods Cross",0.01,IF(Table11[[#This Row],[Location]]="Park City",0.01,IF(Table11[[#This Row],[Location]]="Riverdale",0.01,IF(Table11[[#This Row],[Location]]="Riverton",0.01,IF(Table11[[#This Row],[Location]]="Layton",0.01,IF(Table11[[#This Row],[Location]]="Bend",0.01,IF(Table11[[#This Row],[Location]]="Bend",0.01,IF(Table11[[#This Row],[Location]]="Oakway",0.01,IF(Table11[[#This Row],[Location]]="North Medford",0.01,IF(Table11[[#This Row],[Location]]="South Eugene",0.01,IF(Table11[[#This Row],[Location]]="American Fork",0.01,IF(Table11[[#This Row],[Location]]="Sugar House",0.01,IF(Table11[[#This Row],[Location]]="Bend North",0.01,IF(Table11[[#This Row],[Location]]="South Medford",0.01,IF(Table11[[#This Row],[Location]]="Saratoga Springs",0.01,IF(Table11[[#This Row],[Location]]="Fort Union",0.01,IF(Table11[[#This Row],[Location]]="South Jordan",0.01,IF(Table11[[#This Row],[Location]]="Grants Pass",0.01,IF(Table11[[#This Row],[Location]]="Pocatello",0.01,IF(Table11[[#This Row],[Location]]="Spanish Fork",0.01,IF(Table11[[#This Row],[Location]]="Downtown Boise",0.01,IF(Table11[[#This Row],[Location]]="Boise Town Square",0.01,IF(Table11[[#This Row],[Location]]="Ammon",0.01,IF(Table11[[#This Row],[Location]]="Roseburg",0.01,IF(Table11[[#This Row],[Location]]="Springfield-Oregon",0.01,0.05))))))))))))))))))))))))))))))))) -> 0.05 | L9: =ROUND(F9*K9,2) -> 172.12 | M9: =J9+L9 -> 240.97 | O9: =O8+1 -> 46269 | P9: =COUNTIF(B:B,O9) -> 76
A10: =IF(Table11[[#This Row],[Date]]=0,"",IF(Table11[[#This Row],[Date]]<(Summary!$B$3-6),1,"")) | B10: 46271 | C10: 93 | D10: Brighton | E10: 2888.65 | F10: 2752.57 | G10: =VLOOKUP(Table11[[#This Row],[Store]],'Rates from Tracker'!A:B,2,0) -> Brighton | H10: =VLOOKUP(D10,'Rates from Tracker'!A:C,3,0) -> TSFR Pizza LLC | I10: =VLOOKUP(Table11[[#This Row],[Franchisee]],'Rates from Tracker'!C:D,2,0) -> Schostak | J10: =ROUND(IF(Table11[[#This Row],[Location]]="Belmont Market",Table11[[#This Row],[Column2]]*0.01,IF(Table11[[#This Row],[Location]]="Country Club Centre",Table11[[#This Row],[Column2]]*0.01,IF(Table11[[#This Row],[Location]]="Naval Air Station Norfolk",Table11[[#This Row],[Column2]]*0.005,F10*0.02))),2) -> 55.05 | K10: =IF(Table11[[#This Row],[Location]]="Creekwalk",0.02,IF(Table11[[#This Row],[Location]]="Country Club Centre",0.01,IF(Table11[[#This Row],[Location]]="Lenexa",0.02,IF(Table11[[#This Row],[Location]]="Belmont Market",0.02,IF(Table11[[#This Row],[Location]]="Naval Air Station Norfolk",0.02,IF(Table11[[#This Row],[Location]]="Madison",0.01,IF(Table11[[#This Row],[Location]]="Mobile",0.01,IF(Table11[[#This Row],[Location]]="Decatur",0.01,IF(Table11[[#This Row],[Location]]="Woods Cross",0.01,IF(Table11[[#This Row],[Location]]="Park City",0.01,IF(Table11[[#This Row],[Location]]="Riverdale",0.01,IF(Table11[[#This Row],[Location]]="Riverton",0.01,IF(Table11[[#This Row],[Location]]="Layton",0.01,IF(Table11[[#This Row],[Location]]="Bend",0.01,IF(Table11[[#This Row],[Location]]="Bend",0.01,IF(Table11[[#This Row],[Location]]="Oakway",0.01,IF(Table11[[#This Row],[Location]]="North Medford",0.01,IF(Table11[[#This Row],[Location]]="South Eugene",0.01,IF(Table11[[#This Row],[Location]]="American Fork",0.01,IF(Table11[[#This Row],[Location]]="Sugar House",0.01,IF(Table11[[#This Row],[Location]]="Bend North",0.01,IF(Table11[[#This Row],[Location]]="South Medford",0.01,IF(Table11[[#This Row],[Location]]="Saratoga Springs",0.01,IF(Table11[[#This Row],[Location]]="Fort Union",0.01,IF(Table11[[#This Row],[Location]]="South Jordan",0.01,IF(Table11[[#This Row],[Location]]="Grants Pass",0.01,IF(Table11[[#This Row],[Location]]="Pocatello",0.01,IF(Table11[[#This Row],[Location]]="Spanish Fork",0.01,IF(Table11[[#This Row],[Location]]="Downtown Boise",0.01,IF(Table11[[#This Row],[Location]]="Boise Town Square",0.01,IF(Table11[[#This Row],[Location]]="Ammon",0.01,IF(Table11[[#This Row],[Location]]="Roseburg",0.01,IF(Table11[[#This Row],[Location]]="Springfield-Oregon",0.01,0.05))))))))))))))))))))))))))))))))) -> 0.05 | L10: =ROUND(F10*K10,2) -> 137.63 | M10: =J10+L10 -> 192.68 | O10: =O9+1 -> 46270 | P10: =COUNTIF(B:B,O10) -> 76
A11: =IF(Table11[[#This Row],[Date]]=0,"",IF(Table11[[#This Row],[Date]]<(Summary!$B$3-6),1,"")) | B11: 46271 | C11: 94 | D11: Castle Rock | E11: 5324.11 | F11: 5025.38 | G11: =VLOOKUP(Table11[[#This Row],[Store]],'Rates from Tracker'!A:B,2,0) -> Castle Rock | H11: =VLOOKUP(D11,'Rates from Tracker'!A:C,3,0) -> Best Pizza LLC | I11: =VLOOKUP(Table11[[#This Row],[Franchisee]],'Rates from Tracker'!C:D,2,0) -> Merullo | J11: =ROUND(IF(Table11[[#This Row],[Location]]="Belmont Market",Table11[[#This Row],[Column2]]*0.01,IF(Table11[[#This Row],[Location]]="Country Club Centre",Table11[[#This Row],[Column2]]*0.01,IF(Table11[[#This Row],[Location]]="Naval Air Station Norfolk",Table11[[#This Row],[Column2]]*0.005,F11*0.02))),2) -> 100.51 | K11: =IF(Table11[[#This Row],[Location]]="Creekwalk",0.02,IF(Table11[[#This Row],[Location]]="Country Club Centre",0.01,IF(Table11[[#This Row],[Location]]="Lenexa",0.02,IF(Table11[[#This Row],[Location]]="Belmont Market",0.02,IF(Table11[[#This Row],[Location]]="Naval Air Station Norfolk",0.02,IF(Table11[[#This Row],[Location]]="Madison",0.01,IF(Table11[[#This Row],[Location]]="Mobile",0.01,IF(Table11[[#This Row],[Location]]="Decatur",0.01,IF(Table11[[#This Row],[Location]]="Woods Cross",0.01,IF(Table11[[#This Row],[Location]]="Park City",0.01,IF(Table11[[#This Row],[Location]]="Riverdale",0.01,IF(Table11[[#This Row],[Location]]="Riverton",0.01,IF(Table11[[#This Row],[Location]]="Layton",0.01,IF(Table11[[#This Row],[Location]]="Bend",0.01,IF(Table11[[#This Row],[Location]]="Bend",0.01,IF(Table11[[#This Row],[Location]]="Oakway",0.01,IF(Table11[[#This Row],[Location]]="North Medford",0.01,IF(Table11[[#This Row],[Location]]="South Eugene",0.01,IF(Table11[[#This Row],[Location]]="American Fork",0.01,IF(Table11[[#This Row],[Location]]="Sugar House",0.01,IF(Table11[[#This Row],[Location]]="Bend North",0.01,IF(Table11[[#This Row],[Location]]="South Medford",0.01,IF(Table11[[#This Row],[Location]]="Saratoga Springs",0.01,IF(Table11[[#This Row],[Location]]="Fort Union",0.01,IF(Table11[[#This Row],[Location]]="South Jordan",0.01,IF(Table11[[#This Row],[Location]]="Grants Pass",0.01,IF(Table11[[#This Row],[Location]]="Pocatello",0.01,IF(Table11[[#This Row],[Location]]="Spanish Fork",0.01,IF(Table11[[#This Row],[Location]]="Downtown Boise",0.01,IF(Table11[[#This Row],[Location]]="Boise Town Square",0.01,IF(Table11[[#This Row],[Location]]="Ammon",0.01,IF(Table11[[#This Row],[Location]]="Roseburg",0.01,IF(Table11[[#This Row],[Location]]="Springfield-Oregon",0.01,0.05))))))))))))))))))))))))))))))))) -> 0.05 | L11: =ROUND(F11*K11,2) -> 251.27 | M11: =J11+L11 -> 351.78 | O11: =O10+1 -> 46271 | P11: =COUNTIF(B:B,O11) -> 76
A12: =IF(Table11[[#This Row],[Date]]=0,"",IF(Table11[[#This Row],[Date]]<(Summary!$B$3-6),1,"")) | B12: 46271 | C12: 100 | D12: Howe Bout Arden | E12: 5082.85 | F12: 4745.48 | G12: =VLOOKUP(Table11[[#This Row],[Store]],'Rates from Tracker'!A:B,2,0) -> Howe Bout Arden | H12: =VLOOKUP(D12,'Rates from Tracker'!A:C,3,0) -> Exceed Group Howe Bout Arden | I12: =VLOOKUP(Table11[[#This Row],[Franchisee]],'Rates from Tracker'!C:D,2,0) -> Chawla | J12: =ROUND(IF(Table11[[#This Row],[Location]]="Belmont Market",Table11[[#This Row],[Column2]]*0.01,IF(Table11[[#This Row],[Location]]="Country Club Centre",Table11[[#This Row],[Column2]]*0.01,IF(Table11[[#This Row],[Location]]="Naval Air Station Norfolk",Table11[[#This Row],[Column2]]*0.005,F12*0.02))),2) -> 94.91 | K12: =IF(Table11[[#This Row],[Location]]="Creekwalk",0.02,IF(Table11[[#This Row],[Location]]="Country Club Centre",0.01,IF(Table11[[#This Row],[Location]]="Lenexa",0.02,IF(Table11[[#This Row],[Location]]="Belmont Market",0.02,IF(Table11[[#This Row],[Location]]="Naval Air Station Norfolk",0.02,IF(Table11[[#This Row],[Location]]="Madison",0.01,IF(Table11[[#This Row],[Location]]="Mobile",0.01,IF(Table11[[#This Row],[Location]]="Decatur",0.01,IF(Table11[[#This Row],[Location]]="Woods Cross",0.01,IF(Table11[[#This Row],[Location]]="Park City",0.01,IF(Table11[[#This Row],[Location]]="Riverdale",0.01,IF(Table11[[#This Row],[Location]]="Riverton",0.01,IF(Table11[[#This Row],[Location]]="Layton",0.01,IF(Table11[[#This Row],[Location]]="Bend",0.01,IF(Table11[[#This Row],[Location]]="Bend",0.01,IF(Table11[[#This Row],[Location]]="Oakway",0.01,IF(Table11[[#This Row],[Location]]="North Medford",0.01,IF(Table11[[#This Row],[Location]]="South Eugene",0.01,IF(Table11[[#This Row],[Location]]="American Fork",0.01,IF(Table11[[#This Row],[Location]]="Sugar House",0.01,IF(Table11[[#This Row],[Location]]="Bend North",0.01,IF(Table11[[#This Row],[Location]]="South Medford",0.01,IF(Table11[[#This Row],[Location]]="Saratoga Springs",0.01,IF(Table11[[#This Row],[Location]]="Fort Union",0.01,IF(Table11[[#This Row],[Location]]="South Jordan",0.01,IF(Table11[[#This Row],[Location]]="Grants Pass",0.01,IF(Table11[[#This Row],[Location]]="Pocatello",0.01,IF(Table11[[#This Row],[Location]]="Spanish Fork",0.01,IF(Table11[[#This Row],[Location]]="Downtown Boise",0.01,IF(Table11[[#This Row],[Location]]="Boise Town Square",0.01,IF(Table11[[#This Row],[Location]]="Ammon",0.01,IF(Table11[[#This Row],[Location]]="Roseburg",0.01,IF(Table11[[#This Row],[Location]]="Springfield-Oregon",0.01,0.05))))))))))))))))))))))))))))))))) -> 0.05 | L12: =ROUND(F12*K12,2) -> 237.27 | M12: =J12+L12 -> 332.18
A13: =IF(Table11[[#This Row],[Date]]=0,"",IF(Table11[[#This Row],[Date]]<(Summary!$B$3-6),1,"")) | B13: 46271 | C13: 126 | D13: Bend | E13: 3182.31 | F13: 2931.76 | G13: =VLOOKUP(Table11[[#This Row],[Store]],'Rates from Tracker'!A:B,2,0) -> Bend | H13: =VLOOKUP(D13,'Rates from Tracker'!A:C,3,0) -> SSR Holdings LLC | I13: =VLOOKUP(Table11[[#This Row],[Franchisee]],'Rates from Tracker'!C:D,2,0) -> Bikram | J13: =ROUND(IF(Table11[[#This Row],[Location]]="Belmont Market",Table11[[#This Row],[Column2]]*0.01,IF(Table11[[#This Row],[Location]]="Country Club Centre",Table11[[#This Row],[Column2]]*0.01,IF(Table11[[#This Row],[Location]]="Naval Air Station Norfolk",Table11[[#This Row],[Column2]]*0.005,F13*0.02))),2) -> 58.64 | K13: =IF(Table11[[#This Row],[Location]]="Creekwalk",0.02,IF(Table11[[#This Row],[Location]]="Country Club Centre",0.01,IF(Table11[[#This Row],[Location]]="Lenexa",0.02,IF(Table11[[#This Row],[Location]]="Belmont Market",0.02,IF(Table11[[#This Row],[Location]]="Naval Air Station Norfolk",0.02,IF(Table11[[#This Row],[Location]]="Madison",0.01,IF(Table11[[#This Row],[Location]]="Mobile",0.01,IF(Table11[[#This Row],[Location]]="Decatur",0.01,IF(Table11[[#This Row],[Location]]="Woods Cross",0.01,IF(Table11[[#This Row],[Location]]="Park City",0.01,IF(Table11[[#This Row],[Location]]="Riverdale",0.01,IF(Table11[[#This Row],[Location]]="Riverton",0.01,IF(Table11[[#This Row],[Location]]="Layton",0.01,IF(Table11[[#This Row],[Location]]="Bend",0.01,IF(Table11[[#This Row],[Location]]="Bend",0.01,IF(Table11[[#This Row],[Location]]="Oakway",0.01,IF(Table11[[#This Row],[Location]]="North Medford",0.01,IF(Table11[[#This Row],[Location]]="South Eugene",0.01,IF(Table11[[#This Row],[Location]]="American Fork",0.01,IF(Table11[[#This Row],[Location]]="Sugar House",0.01,IF(Table11[[#This Row],[Location]]="Bend North",0.01,IF(Table11[[#This Row],[Location]]="South Medford",0.01,IF(Table11[[#This Row],[Location]]="Saratoga Springs",0.01,IF(Table11[[#This Row],[Location]]="Fort Union",0.01,IF(Table11[[#This Row],[Location]]="South Jordan",0.01,IF(Table11[[#This Row],[Location]]="Grants Pass",0.01,IF(Table11[[#This Row],[Location]]="Pocatello",0.01,IF(Table11[[#This Row],[Location]]="Spanish Fork",0.01,IF(Table11[[#This Row],[Location]]="Downtown Boise",0.01,IF(Table11[[#This Row],[Location]]="Boise Town Square",0.01,IF(Table11[[#This Row],[Location]]="Ammon",0.01,IF(Table11[[#This Row],[Location]]="Roseburg",0.01,IF(Table11[[#This Row],[Location]]="Springfield-Oregon",0.01,0.05))))))))))))))))))))))))))))))))) -> 0.01 | L13: =ROUND(F13*K13,2) -> 29.32 | M13: =J13+L13 -> 87.96
A14: =IF(Table11[[#This Row],[Date]]=0,"",IF(Table11[[#This Row],[Date]]<(Summary!$B$3-6),1,"")) | B14: 46271 | C14: 133 | D14: Woodhill | E14: 3183.93 | F14: 3013.15 | G14: =VLOOKUP(Table11[[#This Row],[Store]],'Rates from Tracker'!A:B,2,0) -> Woodhill | H14: =VLOOKUP(D14,'Rates from Tracker'!A:C,3,0) -> Rolling Dough LLC | I14: =VLOOKUP(Table11[[#This Row],[Franchisee]],'Rates from Tracker'!C:D,2,0) -> Connolly | J14: =ROUND(IF(Table11[[#This Row],[Location]]="Belmont Market",Table11[[#This Row],[Column2]]*0.01,IF(Table11[[#This Row],[Location]]="Country Club Centre",Table11[[#This Row],[Column2]]*0.01,IF(Table11[[#This Row],[Location]]="Naval Air Station Norfolk",Table11[[#This Row],[Column2]]*0.005,F14*0.02))),2) -> 60.26 | K14: =IF(Table11[[#This Row],[Location]]="Creekwalk",0.02,IF(Table11[[#This Row],[Location]]="Country Club Centre",0.01,IF(Table11[[#This Row],[Location]]="Lenexa",0.02,IF(Table11[[#This Row],[Location]]="Belmont Market",0.02,IF(Table11[[#This Row],[Location]]="Naval Air Station Norfolk",0.02,IF(Table11[[#This Row],[Location]]="Madison",0.01,IF(Table11[[#This Row],[Location]]="Mobile",0.01,IF(Table11[[#This Row],[Location]]="Decatur",0.01,IF(Table11[[#This Row],[Location]]="Woods Cross",0.01,IF(Table11[[#This Row],[Location]]="Park City",0.01,IF(Table11[[#This Row],[Location]]="Riverdale",0.01,IF(Table11[[#This Row],[Location]]="Riverton",0.01,IF(Table11[[#This Row],[Location]]="Layton",0.01,IF(Table11[[#This Row],[Location]]="Bend",0.01,IF(Table11[[#This Row],[Location]]="Bend",0.01,IF(Table11[[#This Row],[Location]]="Oakway",0.01,IF(Table11[[#This Row],[Location]]="North Medford",0.01,IF(Table11[[#This Row],[Location]]="South Eugene",0.01,IF(Table11[[#This Row],[Location]]="American Fork",0.01,IF(Table11[[#This Row],[Location]]="Sugar House",0.01,IF(Table11[[#This Row],[Location]]="Bend North",0.01,IF(Table11[[#This Row],[Location]]="South Medford",0.01,IF(Table11[[#This Row],[Location]]="Saratoga Springs",0.01,IF(Table11[[#This Row],[Location]]="Fort Union",0.01,IF(Table11[[#This Row],[Location]]="South Jordan",0.01,IF(Table11[[#This Row],[Location]]="Grants Pass",0.01,IF(Table11[[#This Row],[Location]]="Pocatello",0.01,IF(Table11[[#This Row],[Location]]="Spanish Fork",0.01,IF(Table11[[#This Row],[Location]]="Downtown Boise",0.01,IF(Table11[[#This Row],[Location]]="Boise Town Square",0.01,IF(Table11[[#This Row],[Location]]="Ammon",0.01,IF(Table11[[#This Row],[Location]]="Roseburg",0.01,IF(Table11[[#This Row],[Location]]="Springfield-Oregon",0.01,0.05))))))))))))))))))))))))))))))))) -> 0.05 | L14: =ROUND(F14*K14,2) -> 150.66 | M14: =J14+L14 -> 210.92
A15: =IF(Table11[[#This Row],[Date]]=0,"",IF(Table11[[#This Row],[Date]]<(Summary!$B$3-6),1,"")) | B15: 46271 | C15: 149 | D15: Westwood Plaza | E15: 3048.46 | F15: 2802.61 | G15: =VLOOKUP(Table11[[#This Row],[Store]],'Rates from Tracker'!A:B,2,0) -> Westwood Plaza | H15: =VLOOKUP(D15,'Rates from Tracker'!A:C,3,0) -> Rolling Dough LLC | I15: =VLOOKUP(Table11[[#This Row],[Franchisee]],'Rates from Tracker'!C:D,2,0) -> Connolly | J15: =ROUND(IF(Table11[[#This Row],[Location]]="Belmont Market",Table11[[#This Row],[Column2]]*0.01,IF(Table11[[#This Row],[Location]]="Country Club Centre",Table11[[#This Row],[Column2]]*0.01,IF(Table11[[#This Row],[Location]]="Naval Air Station Norfolk",Table11[[#This Row],[Column2]]*0.005,F15*0.02))),2) -> 56.05 | K15: =IF(Table11[[#This Row],[Location]]="Creekwalk",0.02,IF(Table11[[#This Row],[Location]]="Country Club Centre",0.01,IF(Table11[[#This Row],[Location]]="Lenexa",0.02,IF(Table11[[#This Row],[Location]]="Belmont Market",0.02,IF(Table11[[#This Row],[Location]]="Naval Air Station Norfolk",0.02,IF(Table11[[#This Row],[Location]]="Madison",0.01,IF(Table11[[#This Row],[Location]]="Mobile",0.01,IF(Table11[[#This Row],[Location]]="Decatur",0.01,IF(Table11[[#This Row],[Location]]="Woods Cross",0.01,IF(Table11[[#This Row],[Location]]="Park City",0.01,IF(Table11[[#This Row],[Location]]="Riverdale",0.01,IF(Table11[[#This Row],[Location]]="Riverton",0.01,IF(Table11[[#This Row],[Location]]="Layton",0.01,IF(Table11[[#This Row],[Location]]="Bend",0.01,IF(Table11[[#This Row],[Location]]="Bend",0.01,IF(Table11[[#This Row],[Location]]="Oakway",0.01,IF(Table11[[#This Row],[Location]]="North Medford",0.01,IF(Table11[[#This Row],[Location]]="South Eugene",0.01,IF(Table11[[#This Row],[Location]]="American Fork",0.01,IF(Table11[[#This Row],[Location]]="Sugar House",0.01,IF(Table11[[#This Row],[Location]]="Bend North",0.01,IF(Table11[[#This Row],[Location]]="South Medford",0.01,IF(Table11[[#This Row],[Location]]="Saratoga Springs",0.01,IF(Table11[[#This Row],[Location]]="Fort Union",0.01,IF(Table11[[#This Row],[Location]]="South Jordan",0.01,IF(Table11[[#This Row],[Location]]="Grants Pass",0.01,IF(Table11[[#This Row],[Location]]="Pocatello",0.01,IF(Table11[[#This Row],[Location]]="Spanish Fork",0.01,IF(Table11[[#This Row],[Location]]="Downtown Boise",0.01,IF(Table11[[#This Row],[Location]]="Boise Town Square",0.01,IF(Table11[[#This Row],[Location]]="Ammon",0.01,IF(Table11[[#This Row],[Location]]="Roseburg",0.01,IF(Table11[[#This Row],[Location]]="Springfield-Oregon",0.01,0.05))))))))))))))))))))))))))))))))) -> 0.05 | L15: =ROUND(F15*K15,2) -> 140.13 | M15: =J15+L15 -> 196.18
A16: =IF(Table11[[#This Row],[Date]]=0,"",IF(Table11[[#This Row],[Date]]<(Summary!$B$3-6),1,"")) | B16: 46271 | C16: 157 | D16: Hamburg | E16: 3925.65 | F16: 3795 | G16: =VLOOKUP(Table11[[#This Row],[Store]],'Rates from Tracker'!A:B,2,0) -> Hamburg #6 | H16: =VLOOKUP(D16,'Rates from Tracker'!A:C,3,0) -> Cool Dough Development, LLC | I16: =VLOOKUP(Table11[[#This Row],[Franchisee]],'Rates from Tracker'!C:D,2,0) -> Denning | J16: =ROUND(IF(Table11[[#This Row],[Location]]="Belmont Market",Table11[[#This Row],[Column2]]*0.01,IF(Table11[[#This Row],[Location]]="Country Club Centre",Table11[[#This Row],[Column2]]*0.01,IF(Table11[[#This Row],[Location]]="Naval Air Station Norfolk",Table11[[#This Row],[Column2]]*0.005,F16*0.02))),2) -> 75.9 | K16: =IF(Table11[[#This Row],[Location]]="Creekwalk",0.02,IF(Table11[[#This Row],[Location]]="Country Club Centre",0.01,IF(Table11[[#This Row],[Location]]="Lenexa",0.02,IF(Table11[[#This Row],[Location]]="Belmont Market",0.02,IF(Table11[[#This Row],[Location]]="Naval Air Station Norfolk",0.02,IF(Table11[[#This Row],[Location]]="Madison",0.01,IF(Table11[[#This Row],[Location]]="Mobile",0.01,IF(Table11[[#This Row],[Location]]="Decatur",0.01,IF(Table11[[#This Row],[Location]]="Woods Cross",0.01,IF(Table11[[#This Row],[Location]]="Park City",0.01,IF(Table11[[#This Row],[Location]]="Riverdale",0.01,IF(Table11[[#This Row],[Location]]="Riverton",0.01,IF(Table11[[#This Row],[Location]]="Layton",0.01,IF(Table11[[#This Row],[Location]]="Bend",0.01,IF(Table11[[#This Row],[Location]]="Bend",0.01,IF(Table11[[#This Row],[Location]]="Oakway",0.01,IF(Table11[[#This Row],[Location]]="North Medford",0.01,IF(Table11[[#This Row],[Location]]="South Eugene",0.01,IF(Table11[[#This Row],[Location]]="American Fork",0.01,IF(Table11[[#This Row],[Location]]="Sugar House",0.01,IF(Table11[[#This Row],[Location]]="Bend North",0.01,IF(Table11[[#This Row],[Location]]="South Medford",0.01,IF(Table11[[#This Row],[Location]]="Saratoga Springs",0.01,IF(Table11[[#This Row],[Location]]="Fort Union",0.01,IF(Table11[[#This Row],[Location]]="South Jordan",0.01,IF(Table11[[#This Row],[Location]]="Grants Pass",0.01,IF(Table11[[#This Row],[Location]]="Pocatello",0.01,IF(Table11[[#This Row],[Location]]="Spanish Fork",0.01,IF(Table11[[#This Row],[Location]]="Downtown Boise",0.01,IF(Table11[[#This Row],[Location]]="Boise Town Square",0.01,IF(Table11[[#This Row],[Location]]="Ammon",0.01,IF(Table11[[#This Row],[Location]]="Roseburg",0.01,IF(Table11[[#This Row],[Location]]="Springfield-Oregon",0.01,0.05))))))))))))))))))))))))))))))))) -> 0.05 | L16: =ROUND(F16*K16,2) -> 189.75 | M16: =J16+L16 -> 265.65
A17: =IF(Table11[[#This Row],[Date]]=0,"",IF(Table11[[#This Row],[Date]]<(Summary!$B$3-6),1,"")) | B17: 46271 | C17: 158 | D17: McCaslin Marketplace | E17: 3471.46 | F17: 3287.16 | G17: =VLOOKUP(Table11[[#This Row],[Store]],'Rates from Tracker'!A:B,2,0) -> McCaslin Marketplace | H17: =VLOOKUP(D17,'Rates from Tracker'!A:C,3,0) -> Best Pizza LLC | I17: =VLOOKUP(Table11[[#This Row],[Franchisee]],'Rates from Tracker'!C:D,2,0) -> Merullo | J17: =ROUND(IF(Table11[[#This Row],[Location]]="Belmont Market",Table11[[#This Row],[Column2]]*0.01,IF(Table11[[#This Row],[Location]]="Country Club Centre",Table11[[#This Row],[Column2]]*0.01,IF(Table11[[#This Row],[Location]]="Naval Air Station Norfolk",Table11[[#This Row],[Column2]]*0.005,F17*0.02))),2) -> 65.74 | K17: =IF(Table11[[#This Row],[Location]]="Creekwalk",0.02,IF(Table11[[#This Row],[Location]]="Country Club Centre",0.01,IF(Table11[[#This Row],[Location]]="Lenexa",0.02,IF(Table11[[#This Row],[Location]]="Belmont Market",0.02,IF(Table11[[#This Row],[Location]]="Naval Air Station Norfolk",0.02,IF(Table11[[#This Row],[Location]]="Madison",0.01,IF(Table11[[#This Row],[Location]]="Mobile",0.01,IF(Table11[[#This Row],[Location]]="Decatur",0.01,IF(Table11[[#This Row],[Location]]="Woods Cross",0.01,IF(Table11[[#This Row],[Location]]="Park City",0.01,IF(Table11[[#This Row],[Location]]="Riverdale",0.01,IF(Table11[[#This Row],[Location]]="Riverton",0.01,IF(Table11[[#This Row],[Location]]="Layton",0.01,IF(Table11[[#This Row],[Location]]="Bend",0.01,IF(Table11[[#This Row],[Location]]="Bend",0.01,IF(Table11[[#This Row],[Location]]="Oakway",0.01,IF(Table11[[#This Row],[Location]]="North Medford",0.01,IF(Table11[[#This Row],[Location]]="South Eugene",0.01,IF(Table11[[#This Row],[Location]]="American Fork",0.01,IF(Table11[[#This Row],[Location]]="Sugar House",0.01,IF(Table11[[#This Row],[Location]]="Bend North",0.01,IF(Table11[[#This Row],[Location]]="South Medford",0.01,IF(Table11[[#This Row],[Location]]="Saratoga Springs",0.01,IF(Table11[[#This Row],[Location]]="Fort Union",0.01,IF(Table11[[#This Row],[Location]]="South Jordan",0.01,IF(Table11[[#This Row],[Location]]="Grants Pass",0.01,IF(Table11[[#This Row],[Location]]="Pocatello",0.01,IF(Table11[[#This Row],[Location]]="Spanish Fork",0.01,IF(Table11[[#This Row],[Location]]="Downtown Boise",0.01,IF(Table11[[#This Row],[Location]]="Boise Town Square",0.01,IF(Table11[[#This Row],[Location]]="Ammon",0.01,IF(Table11[[#This Row],[Location]]="Roseburg",0.01,IF(Table11[[#This Row],[Location]]="Springfield-Oregon",0.01,0.05))))))))))))))))))))))))))))))))) -> 0.05 | L17: =ROUND(F17*K17,2) -> 164.36 | M17: =J17+L17 -> 230.1
A18: =IF(Table11[[#This Row],[Date]]=0,"",IF(Table11[[#This Row],[Date]]<(Summary!$B$3-6),1,"")) | B18: 46271 | C18: 159 | D18: North Charleston | E18: 2076.13 | F18: 1861.01 | G18: =VLOOKUP(Table11[[#This Row],[Store]],'Rates from Tracker'!A:B,2,0) -> North Charleston | H18: =VLOOKUP(D18,'Rates from Tracker'!A:C,3,0) -> Rolling Dough LLC | I18: =VLOOKUP(Table11[[#This Row],[Franchisee]],'Rates from Tracker'!C:D,2,0) -> Connolly | J18: =ROUND(IF(Table11[[#This Row],[Location]]="Belmont Market",Table11[[#This Row],[Column2]]*0.01,IF(Table11[[#This Row],[Location]]="Country Club Centre",Table11[[#This Row],[Column2]]*0.01,IF(Table11[[#This Row],[Location]]="Naval Air Station Norfolk",Table11[[#This Row],[Column2]]*0.005,F18*0.02))),2) -> 37.22 | K18: =IF(Table11[[#This Row],[Location]]="Creekwalk",0.02,IF(Table11[[#This Row],[Location]]="Country Club Centre",0.01,IF(Table11[[#This Row],[Location]]="Lenexa",0.02,IF(Table11[[#This Row],[Location]]="Belmont Market",0.02,IF(Table11[[#This Row],[Location]]="Naval Air Station Norfolk",0.02,IF(Table11[[#This Row],[Location]]="Madison",0.01,IF(Table11[[#This Row],[Location]]="Mobile",0.01,IF(Table11[[#This Row],[Location]]="Decatur",0.01,IF(Table11[[#This Row],[Location]]="Woods Cross",0.01,IF(Table11[[#This Row],[Location]]="Park City",0.01,IF(Table11[[#This Row],[Location]]="Riverdale",0.01,IF(Table11[[#This Row],[Location]]="Riverton",0.01,IF(Table11[[#This Row],[Location]]="Layton",0.01,IF(Table11[[#This Row],[Location]]="Bend",0.01,IF(Table11[[#This Row],[Location]]="Bend",0.01,IF(Table11[[#This Row],[Location]]="Oakway",0.01,IF(Table11[[#This Row],[Location]]="North Medford",0.01,IF(Table11[[#This Row],[Location]]="South Eugene",0.01,IF(Table11[[#This Row],[Location]]="American Fork",0.01,IF(Table11[[#This Row],[Location]]="Sugar House",0.01,IF(Table11[[#This Row],[Location]]="Bend North",0.01,IF(Table11[[#This Row],[Location]]="South Medford",0.01,IF(Table11[[#This Row],[Location]]="Saratoga Springs",0.01,IF(Table11[[#This Row],[Location]]="Fort Union",0.01,IF(Table11[[#This Row],[Location]]="South Jordan",0.01,IF(Table11[[#This Row],[Location]]="Grants Pass",0.01,IF(Table11[[#This Row],[Location]]="Pocatello",0.01,IF(Table11[[#This Row],[Location]]="Spanish Fork",0.01,IF(Table11[[#This Row],[Location]]="Downtown Boise",0.01,IF(Table11[[#This Row],[Location]]="Boise Town Square",0.01,IF(Table11[[#This Row],[Location]]="Ammon",0.01,IF(Table11[[#This Row],[Location]]="Roseburg",0.01,IF(Table11[[#This Row],[Location]]="Springfield-Oregon",0.01,0.05))))))))))))))))))))))))))))))))) -> 0.05 | L18: =ROUND(F18*K18,2) -> 93.05 | M18: =J18+L18 -> 130.27
A19: =IF(Table11[[#This Row],[Date]]=0,"",IF(Table11[[#This Row],[Date]]<(Summary!$B$3-6),1,"")) | B19: 46271 | C19: 161 | D19: Chico | E19: 4851.83 | F19: 4503.28 | G19: =VLOOKUP(Table11[[#This Row],[Store]],'Rates from Tracker'!A:B,2,0) -> Chico | H19: =VLOOKUP(D19,'Rates from Tracker'!A:C,3,0) -> Exceed Group Chico | I19: =VLOOKUP(Table11[[#This Row],[Franchisee]],'Rates from Tracker'!C:D,2,0) -> Chawla | J19: =ROUND(IF(Table11[[#This Row],[Location]]="Belmont Market",Table11[[#This Row],[Column2]]*0.01,IF(Table11[[#This Row],[Location]]="Country Club Centre",Table11[[#This Row],[Column2]]*0.01,IF(Table11[[#This Row],[Location]]="Naval Air Station Norfolk",Table11[[#This Row],[Column2]]*0.005,F19*0.02))),2) -> 90.07 | K19: =IF(Table11[[#This Row],[Location]]="Creekwalk",0.02,IF(Table11[[#This Row],[Location]]="Country Club Centre",0.01,IF(Table11[[#This Row],[Location]]="Lenexa",0.02,IF(Table11[[#This Row],[Location]]="Belmont Market",0.02,IF(Table11[[#This Row],[Location]]="Naval Air Station Norfolk",0.02,IF(Table11[[#This Row],[Location]]="Madison",0.01,IF(Table11[[#This Row],[Location]]="Mobile",0.01,IF(Table11[[#This Row],[Location]]="Decatur",0.01,IF(Table11[[#This Row],[Location]]="Woods Cross",0.01,IF(Table11[[#This Row],[Location]]="Park City",0.01,IF(Table11[[#This Row],[Location]]="Riverdale",0.01,IF(Table11[[#This Row],[Location]]="Riverton",0.01,IF(Table11[[#This Row],[Location]]="Layton",0.01,IF(Table11[[#This Row],[Location]]="Bend",0.01,IF(Table11[[#This Row],[Location]]="Bend",0.01,IF(Table11[[#This Row],[Location]]="Oakway",0.01,IF(Table11[[#This Row],[Location]]="North Medford",0.01,IF(Table11[[#This Row],[Location]]="South Eugene",0.01,IF(Table11[[#This Row],[Location]]="American Fork",0.01,IF(Table11[[#This Row],[Location]]="Sugar House",0.01,IF(Table11[[#This Row],[Location]]="Bend North",0.01,IF(Table11[[#This Row],[Location]]="South Medford",0.01,IF(Table11[[#This Row],[Location]]="Saratoga Springs",0.01,IF(Table11[[#This Row],[Location]]="Fort Union",0.01,IF(Table11[[#This Row],[Location]]="South Jordan",0.01,IF(Table11[[#This Row],[Location]]="Grants Pass",0.01,IF(Table11[[#This Row],[Location]]="Pocatello",0.01,IF(Table11[[#This Row],[Location]]="Spanish Fork",0.01,IF(Table11[[#This Row],[Location]]="Downtown Boise",0.01,IF(Table11[[#This Row],[Location]]="Boise Town Square",0.01,IF(Table11[[#This Row],[Location]]="Ammon",0.01,IF(Table11[[#This Row],[Location]]="Roseburg",0.01,IF(Table11[[#This Row],[Location]]="Springfield-Oregon",0.01,0.05))))))))))))))))))))))))))))))))) -> 0.05 | L19: =ROUND(F19*K19,2) -> 225.16 | M19: =J19+L19 -> 315.23
A20: =IF(Table11[[#This Row],[Date]]=0,"",IF(Table11[[#This Row],[Date]]<(Summary!$B$3-6),1,"")) | B20: 46271 | C20: 163 | D20: Forest Trace | E20: 4862.07 | F20: 4406.8 | G20: =VLOOKUP(Table11[[#This Row],[Store]],'Rates from Tracker'!A:B,2,0) -> Forest Trace | H20: =VLOOKUP(D20,'Rates from Tracker'!A:C,3,0) -> Best Pizza LLC | I20: =VLOOKUP(Table11[[#This Row],[Franchisee]],'Rates from Tracker'!C:D,2,0) -> Merullo | J20: =ROUND(IF(Table11[[#This Row],[Location]]="Belmont Market",Table11[[#This Row],[Column2]]*0.01,IF(Table11[[#This Row],[Location]]="Country Club Centre",Table11[[#This Row],[Column2]]*0.01,IF(Table11[[#This Row],[Location]]="Naval Air Station Norfolk",Table11[[#This Row],[Column2]]*0.005,F20*0.02))),2) -> 88.14 | K20: =IF(Table11[[#This Row],[Location]]="Creekwalk",0.02,IF(Table11[[#This Row],[Location]]="Country Club Centre",0.01,IF(Table11[[#This Row],[Location]]="Lenexa",0.02,IF(Table11[[#This Row],[Location]]="Belmont Market",0.02,IF(Table11[[#This Row],[Location]]="Naval Air Station Norfolk",0.02,IF(Table11[[#This Row],[Location]]="Madison",0.01,IF(Table11[[#This Row],[Location]]="Mobile",0.01,IF(Table11[[#This Row],[Location]]="Decatur",0.01,IF(Table11[[#This Row],[Location]]="Woods Cross",0.01,IF(Table11[[#This Row],[Location]]="Park City",0.01,IF(Table11[[#This Row],[Location]]="Riverdale",0.01,IF(Table11[[#This Row],[Location]]="Riverton",0.01,IF(Table11[[#This Row],[Location]]="Layton",0.01,IF(Table11[[#This Row],[Location]]="Bend",0.01,IF(Table11[[#This Row],[Location]]="Bend",0.01,IF(Table11[[#This Row],[Location]]="Oakway",0.01,IF(Table11[[#This Row],[Location]]="North Medford",0.01,IF(Table11[[#This Row],[Location]]="South Eugene",0.01,IF(Table11[[#This Row],[Location]]="American Fork",0.01,IF(Table11[[#This Row],[Location]]="Sugar House",0.01,IF(Table11[[#This Row],[Location]]="Bend North",0.01,IF(Table11[[#This Row],[Location]]="South Medford",0.01,IF(Table11[[#This Row],[Location]]="Saratoga Springs",0.01,IF(Table11[[#This Row],[Location]]="Fort Union",0.01,IF(Table11[[#This Row],[Location]]="South Jordan",0.01,IF(Table11[[#This Row],[Location]]="Grants Pass",0.01,IF(Table11[[#This Row],[Location]]="Pocatello",0.01,IF(Table11[[#This Row],[Location]]="Spanish Fork",0.01,IF(Table11[[#This Row],[Location]]="Downtown Boise",0.01,IF(Table11[[#This Row],[Location]]="Boise Town Square",0.01,IF(Table11[[#This Row],[Location]]="Ammon",0.01,IF(Table11[[#This Row],[Location]]="Roseburg",0.01,IF(Table11[[#This Row],[Location]]="Springfield-Oregon",0.01,0.05))))))))))))))))))))))))))))))))) -> 0.05 | L20: =ROUND(F20*K20,2) -> 220.34 | M20: =J20+L20 -> 308.48
